// Try Catch --  Manejo de errores

let num1 = 10;
let num3 = 23.

try {
    console.log(num1)
    console.log(num2)
    console.log(num3)
} catch (ReferenceError) {
    console.log(ReferenceError)
    console.log(num3)
}

